(dp1
S'output'
p2
S'<type \'exceptions.RuntimeError\'> Failure to connect, tried 5 times:\nTraceback (most recent call last):\n  File "/Users/IshanB/Documents/Developer/pyCharm/StuffShare/web2py/gluon/dal.py", line 8038, in __init__\n    self._adapter = ADAPTERS[self._dbname](**kwargs)\n  File "/Users/IshanB/Documents/Developer/pyCharm/StuffShare/web2py/gluon/dal.py", line 700, in __call__\n    obj = super(AdapterMeta, cls).__call__(*args, **kwargs)\n  File "/Users/IshanB/Documents/Developer/pyCharm/StuffShare/web2py/gluon/dal.py", line 2749, in __init__\n    if do_connect: self.reconnect()\n  File "/Users/IshanB/Documents/Developer/pyCharm/StuffShare/web2py/gluon/dal.py", line 659, in reconnect\n    self.connection = f()\n  File "/Users/IshanB/Documents/Developer/pyCharm/StuffShare/web2py/gluon/dal.py", line 2747, in connector\n    return self.driver.connect(**driver_args)\n  File "/Users/IshanB/Documents/Developer/pyCharm/StuffShare/web2py/gluon/contrib/pymysql/__init__.py", line 93, in Connect\n    return Connection(*args, **kwargs)\n  File "/Users/IshanB/Documents/Developer/pyCharm/StuffShare/web2py/gluon/contrib/pymysql/connections.py", line 575, in __init__\n    self._connect()\n  File "/Users/IshanB/Documents/Developer/pyCharm/StuffShare/web2py/gluon/contrib/pymysql/connections.py", line 741, in _connect\n    self._request_authentication()\n  File "/Users/IshanB/Documents/Developer/pyCharm/StuffShare/web2py/gluon/contrib/pymysql/connections.py", line 796, in _request_authentication\n    self._send_authentication()\n  File "/Users/IshanB/Documents/Developer/pyCharm/StuffShare/web2py/gluon/contrib/pymysql/connections.py", line 845, in _send_authentication\n    auth_packet.check_error()\n  File "/Users/IshanB/Documents/Developer/pyCharm/StuffShare/web2py/gluon/contrib/pymysql/connections.py", line 341, in check_error\n    raise_mysql_exception(self.__data)\n  File "/Users/IshanB/Documents/Developer/pyCharm/StuffShare/web2py/gluon/contrib/pymysql/err.py", line 142, in raise_mysql_exception\n    _check_mysql_exception(errinfo)\n  File "/Users/IshanB/Documents/Developer/pyCharm/StuffShare/web2py/gluon/contrib/pymysql/err.py", line 135, in _check_mysql_exception\n    raise errorclass, (errno,errorvalue)\nOperationalError: (1045, u"Access denied for user \'root\'@\'localhost\' (using password: YES)")\n'
p3
sS'layer'
p4
S'/Users/IshanB/Documents/Developer/pyCharm/StuffShare/web2py/applications/StuffShare/models/db.py'
p5
sS'code'
p6
S"# db = DAL('mysql://clan10:clan10@clan10.pythonanywhere.com/mysql.server/clan10$stuffshare')\ndb = DAL('mysql://root:5693ib@localhost:3306/stuffshare')\nfrom gluon.tools import Auth\nauth = Auth(db)\nauth.define_tables(username=False,signature=False)\n\nauth.settings.actions_disabled.append('request_reset_password')\nauth.settings.actions_disabled.append('retrieve_username')\n\n\ndb.define_table('posessions',\n    Field('id', 'integer', unique=True, requires=[IS_NOT_EMPTY(), IS_ALPHANUMERIC()]),\n    Field('user_id', 'integer', requires=[IS_NOT_EMPTY(), IS_IN_DB(db, db.auth_user.id)]),\n    Field('item_name', 'text', requires=[IS_NOT_EMPTY()]),\n    Field('notes', 'text', requires=[IS_NOT_EMPTY()]),\n    Field('quality', 'text', requires=[IS_NOT_EMPTY()]),\n    Field('return_date', 'date', requires=[IS_NOT_EMPTY()]),\n    Field('picture', 'upload'))\n\ndb.posessions.quality.requires=IS_IN_SET(('Poor','Mediocre','Average', 'Good', 'Excellent', 'Like New'))\ndb.posessions.id.readable = False\ndb.posessions.user_id.readable = False\n\n\ndb.define_table('friends',\n    Field('id', 'integer', unique=True, requires=[IS_NOT_EMPTY(), IS_ALPHANUMERIC()]),\n    Field('user_id', 'integer', db.auth_user, requires=[IS_NOT_EMPTY(), IS_ALPHANUMERIC(), IS_IN_DB(db, db.auth_user.id)]),\n    Field('friend_id', 'integer', db.auth_user, requires=[IS_NOT_EMPTY(), IS_ALPHANUMERIC(), IS_IN_DB(db, db.auth_user.id)]))\n\ndb.friends.id.readable = False\n"
p7
sS'snapshot'
p8
(dp9
sS'traceback'
p10
S'Traceback (most recent call last):\n  File "/Users/IshanB/Documents/Developer/pyCharm/StuffShare/web2py/gluon/restricted.py", line 224, in restricted\n    exec ccode in environment\n  File "/Users/IshanB/Documents/Developer/pyCharm/StuffShare/web2py/applications/StuffShare/models/db.py", line 2, in <module>\n    db = DAL(\'mysql://root:5693ib@localhost:3306/stuffshare\')\n  File "/Users/IshanB/Documents/Developer/pyCharm/StuffShare/web2py/gluon/dal.py", line 8060, in __init__\n    raise RuntimeError("Failure to connect, tried %d times:\\n%s" % (attempts, tb))\nRuntimeError: Failure to connect, tried 5 times:\nTraceback (most recent call last):\n  File "/Users/IshanB/Documents/Developer/pyCharm/StuffShare/web2py/gluon/dal.py", line 8038, in __init__\n    self._adapter = ADAPTERS[self._dbname](**kwargs)\n  File "/Users/IshanB/Documents/Developer/pyCharm/StuffShare/web2py/gluon/dal.py", line 700, in __call__\n    obj = super(AdapterMeta, cls).__call__(*args, **kwargs)\n  File "/Users/IshanB/Documents/Developer/pyCharm/StuffShare/web2py/gluon/dal.py", line 2749, in __init__\n    if do_connect: self.reconnect()\n  File "/Users/IshanB/Documents/Developer/pyCharm/StuffShare/web2py/gluon/dal.py", line 659, in reconnect\n    self.connection = f()\n  File "/Users/IshanB/Documents/Developer/pyCharm/StuffShare/web2py/gluon/dal.py", line 2747, in connector\n    return self.driver.connect(**driver_args)\n  File "/Users/IshanB/Documents/Developer/pyCharm/StuffShare/web2py/gluon/contrib/pymysql/__init__.py", line 93, in Connect\n    return Connection(*args, **kwargs)\n  File "/Users/IshanB/Documents/Developer/pyCharm/StuffShare/web2py/gluon/contrib/pymysql/connections.py", line 575, in __init__\n    self._connect()\n  File "/Users/IshanB/Documents/Developer/pyCharm/StuffShare/web2py/gluon/contrib/pymysql/connections.py", line 741, in _connect\n    self._request_authentication()\n  File "/Users/IshanB/Documents/Developer/pyCharm/StuffShare/web2py/gluon/contrib/pymysql/connections.py", line 796, in _request_authentication\n    self._send_authentication()\n  File "/Users/IshanB/Documents/Developer/pyCharm/StuffShare/web2py/gluon/contrib/pymysql/connections.py", line 845, in _send_authentication\n    auth_packet.check_error()\n  File "/Users/IshanB/Documents/Developer/pyCharm/StuffShare/web2py/gluon/contrib/pymysql/connections.py", line 341, in check_error\n    raise_mysql_exception(self.__data)\n  File "/Users/IshanB/Documents/Developer/pyCharm/StuffShare/web2py/gluon/contrib/pymysql/err.py", line 142, in raise_mysql_exception\n    _check_mysql_exception(errinfo)\n  File "/Users/IshanB/Documents/Developer/pyCharm/StuffShare/web2py/gluon/contrib/pymysql/err.py", line 135, in _check_mysql_exception\n    raise errorclass, (errno,errorvalue)\nOperationalError: (1045, u"Access denied for user \'root\'@\'localhost\' (using password: YES)")\n\n'
p11
s.